<?xml version="1.0" encoding="utf-8"?>
<!-- This URDF was automatically created by SolidWorks to URDF Exporter! Originally created by Stephen Brawner (brawner@gmail.com) 
     Commit Version: 1.5.0-0-g9aa0fdb  Build Version: 1.5.7004.21443
     For more information, please see http://wiki.ros.org/sw_urdf_exporter -->
<robot
  name="MOTOMAN_UPJ.URDF">
  <link
    name="base_link">
    <inertial>
      <origin
        xyz="-0.00044445 -0.036253 0.0076717"
        rpy="0 0 0" />
      <mass
        value="4.0409" />
      <inertia
        ixx="0.012287"
        ixy="0.00083352"
        ixz="6.0969E-06"
        iyy="0.023976"
        iyz="-1.038E-05"
        izz="0.023287" />
    </inertial>
    <visual>
      <origin
        xyz="0 0 0"
        rpy="0 0 0" />
      <geometry>
        <mesh
          filename="package://vis_lecture/MOTOMAN_UPJ.URDF/meshes/base_link.STL" />
      </geometry>
      <material
        name="">
        <color
          rgba="0.75294 0.75294 0.75294 1" />
      </material>
    </visual>
    <collision>
      <origin
        xyz="0 0 0"
        rpy="0 0 0" />
      <geometry>
        <mesh
          filename="package://vis_lecture/MOTOMAN_UPJ.URDF/meshes/base_link.STL" />
      </geometry>
    </collision>
  </link>
  <link
    name="rotary_head">
    <inertial>
      <origin
        xyz="-0.0019906 0.091523 0.0031222"
        rpy="0 0 0" />
      <mass
        value="3.4064" />
      <inertia
        ixx="0.01808"
        ixy="-7.2413E-05"
        ixz="-2.1162E-05"
        iyy="0.0098752"
        iyz="-0.00068691"
        izz="0.019643" />
    </inertial>
    <visual>
      <origin
      xyz="-0.046649 -0.025684 -0.007692"
      rpy="0 0 0" />
      <geometry>
        <mesh
          filename="package://vis_lecture/MOTOMAN_UPJ.URDF/meshes/rotary_head.STL" />
      </geometry>
      <material
        name="">
        <color
          rgba="0.75294 0.75294 0.75294 1" />
      </material>
    </visual>
    <collision>
      <origin
        xyz="-0.046649 -0.025684 -0.007692"
        rpy="0 0 0" />
      <geometry>
        <mesh
          filename="package://vis_lecture/MOTOMAN_UPJ.URDF/meshes/rotary_head.STL" />
      </geometry>
    </collision>
  </link>
  <joint
    name="rotary_head"
    type="continuous">
    <origin
      xyz="0.046649 -0.007692 0.025684"
      rpy="1.5708 0 0" />
    <parent
      link="base_link" />
    <child
      link="rotary_head" />
    <axis
      xyz="0 1 0" />
    <safety_controller
      k_velocity="0" />
  </joint>
  <link
    name="lower_arm">
    <inertial>
      <origin
        xyz="-0.00047836 0.11708 -0.0041285"
        rpy="0 0 0" />
      <mass
        value="4.1334" />
      <inertia
        ixx="0.043044"
        ixy="8.3436E-05"
        ixz="1.9562E-05"
        iyy="0.011436"
        iyz="-0.00071152"
        izz="0.037002" />
    </inertial>
    <visual>
      <origin
        xyz="-0.046649 -0.193684 -0.007692"
        rpy="0 0 0" />
      <geometry>
        <mesh
          filename="package://vis_lecture/MOTOMAN_UPJ.URDF/meshes/lower_arm.STL" />
      </geometry>
      <material
        name="">
        <color
          rgba="0 0 1 1" />
      </material>
    </visual>
    <collision>
      <origin
        xyz="0 0 0"
        rpy="0 0 0" />
      <geometry>
        <mesh
          filename="package://vis_lecture/MOTOMAN_UPJ.URDF/meshes/lower_arm.STL" />
      </geometry>
    </collision>
  </link>
  <joint
    name="lower_arm"
    type="continuous">
    <origin
      xyz="0 0.168 0"
      rpy="0 0 -0.17433" />
    <parent
      link="rotary_head" />
    <child
      link="lower_arm" />
    <axis
      xyz="0 0 1" />
    <safety_controller
      k_velocity="0" />
  </joint>
  <link
    name="upper_arm">
    <inertial>
      <origin
        xyz="-0.040633 0.27227 0.065032"
        rpy="0 0 0" />
      <mass
        value="2.5359" />
      <inertia
        ixx="0.0061646"
        ixy="-0.00029352"
        ixz="6.8888E-07"
        iyy="0.0085043"
        iyz="1.3502E-06"
        izz="0.0097574" />
    </inertial>
    <visual>
      <origin
        xyz="-0.0742426653426694 -0.431071396551031 -0.0206920000000001"
        rpy="0 0 0.18865" />
      <geometry>
        <mesh
          filename="package://vis_lecture/MOTOMAN_UPJ.URDF/meshes/upper_arm.STL" />
      </geometry>
      <material
        name="">
        <color
          rgba="0.75294 0.75294 0.75294 1" />
      </material>
    </visual>
    <collision>
      <origin
        xyz="0 0 0"
        rpy="0 0 0" />
      <geometry>
        <mesh
          filename="package://vis_lecture/MOTOMAN_UPJ.URDF/meshes/upper_arm.STL" />
      </geometry>
    </collision>
  </link>
  <joint
    name="upper_arm"
    type="continuous">
    <origin
      xyz="0.0742426653426694 0.238387396551031 0.0130000000000001"
      rpy="0 0 -0.18865" />
    <parent
      link="lower_arm" />
    <child
      link="upper_arm" />
    <axis
      xyz="0 0 1" />
    <safety_controller
      k_velocity="0" />
  </joint>
  <link
    name="forearm_twisting">
    <inertial>
      <origin
        xyz="0.062471 0.049493 0.052"
        rpy="0 0 0" />
      <mass
        value="1.9049" />
      <inertia
        ixx="0.0027746"
        ixy="6.0048E-05"
        ixz="-1.2843E-08"
        iyy="0.0062337"
        iyz="-5.1563E-09"
        izz="0.006131" />
    </inertial>
    <visual>
      <origin
        xyz="0 0 0"
        rpy="0 0 0" />
      <geometry>
        <mesh
          filename="package://vis_lecture/MOTOMAN_UPJ.URDF/meshes/forearm_twisting.STL" />
      </geometry>
      <material
        name="">
        <color
          rgba="0 0 1 1" />
      </material>
    </visual>
    <collision>
      <origin
        xyz="0 0 0"
        rpy="0 0 0" />
      <geometry>
        <mesh
          filename="package://vis_lecture/MOTOMAN_UPJ.URDF/meshes/forearm_twisting.STL" />
      </geometry>
    </collision>
  </link>
  <joint
    name="forearm_twisting"
    type="continuous">
    <origin
      xyz="0.0742426653426694 0.238387396551031 0.0130000000000001"
      rpy="0 0 0" />
    <parent
      link="upper_arm" />
    <child
      link="forearm_twisting" />
    <axis
      xyz="1 0 0" />
    <safety_controller
      k_velocity="0" />
  </joint>

  <link
    name="wrist">
    <inertial>
      <origin
        xyz="0.021009 1.1102E-16 0.035"
        rpy="0 0 0" />
      <mass
        value="0.4363" />
      <inertia
        ixx="0.00029652"
        ixy="0"
        ixz="-6.4641E-20"
        iyy="0.00054116"
        iyz="-6.7178E-21"
        izz="0.00054168" />
    </inertial>
    <visual>
      <origin
        xyz="0 0 0"
        rpy="0 0 0" />
      <geometry>
        <mesh
          filename="package://vis_lecture/MOTOMAN_UPJ.URDF/meshes/wrist.STL" />
      </geometry>
      <material
        name="">
        <color
          rgba="0 0 1 1" />
      </material>
    </visual>
    <collision>
      <origin
        xyz="0 0 0"
        rpy="0 0 0" />
      <geometry>
        <mesh
          filename="package://vis_lecture/MOTOMAN_UPJ.URDF/meshes/wrist.STL" />
      </geometry>
    </collision>
  </link>
  <joint
    name="wrist"
    type="continuous">
    <origin
      xyz="0.147 0.047 0.017"
      rpy="0 0 -0.5313477705325" />
    <parent
      link="forearm_twisting" />
    <child
      link="wrist" />
    <axis
      xyz="0 0 1" />
    <safety_controller
      k_velocity="0" />
  </joint>
  <link
    name="axis6">
    <inertial>
      <origin
        xyz="-0.00048171 9.9825E-05 1.1102E-16"
        rpy="0 0 0" />
      <mass
        value="0.021672" />
      <inertia
        ixx="1.105E-05"
        ixy="-1.0572E-08"
        ixz="-5.2054E-21"
        iyy="5.8193E-06"
        iyz="0"
        izz="5.785E-06" />
    </inertial>
    <visual>
      <origin
        xyz="0 0 0"
        rpy="0 0 0" />
      <geometry>
        <mesh
          filename="package://vis_lecture/MOTOMAN_UPJ.URDF/meshes/axis6.STL" />
      </geometry>
      <material
        name="">
        <color
          rgba="0.75294 0.75294 0.75294 1" />
      </material>
    </visual>
    <collision>
      <origin
        xyz="0 0 0"
        rpy="0 0 0" />
      <geometry>
        <mesh
          filename="package://vis_lecture/MOTOMAN_UPJ.URDF/meshes/axis6.STL" />
      </geometry>
    </collision>
  </link>
  <joint
    name="axis6"
    type="continuous">
    <origin
      xyz="0.0820951659734655 0 0.035"
      rpy="1.54103918016642 0 0" />
    <parent
      link="wrist" />
    <child
      link="axis6" />
    <axis
      xyz="1 0 0" />
    <safety_controller
      k_velocity="0" />
  </joint>
</robot>
